2023-04-10 19:28:46.246 [   DEBUG] (         protocol.py: 331) Exception caught
Traceback (most recent call last):
  File "C:\Users\ctcheung\.conda\envs\hfnvenv\lib\site-packages\rpyc\core\protocol.py", line 324, in _dispatch_request
    res = self._HANDLERS[handler](self, *args)
  File "C:\Users\ctcheung\.conda\envs\hfnvenv\lib\site-packages\rpyc\core\protocol.py", line 609, in _handle_call
    return obj(*args, **dict(kwargs))
  File "C:\Users\ctcheung\OneDrive - The University of Chicago\UChicago Postgrad\Research\High Magnetic Field NV\program\diamonddash\hardware\laser\laser.py", line 205, in get_laser_power
    return float(self.send_query("?P"))
  File "C:\Users\ctcheung\OneDrive - The University of Chicago\UChicago Postgrad\Research\High Magnetic Field NV\program\diamonddash\hardware\laser\laser.py", line 48, in send_query
    return super().send(input).encode('ASCII')
AttributeError: 'int' object has no attribute 'encode'
2023-04-10 19:28:46.753 [   DEBUG] (         protocol.py: 331) Exception caught
Traceback (most recent call last):
  File "C:\Users\ctcheung\.conda\envs\hfnvenv\lib\site-packages\rpyc\core\protocol.py", line 324, in _dispatch_request
    res = self._HANDLERS[handler](self, *args)
  File "C:\Users\ctcheung\.conda\envs\hfnvenv\lib\site-packages\rpyc\core\protocol.py", line 609, in _handle_call
    return obj(*args, **dict(kwargs))
  File "C:\Users\ctcheung\OneDrive - The University of Chicago\UChicago Postgrad\Research\High Magnetic Field NV\program\diamonddash\hardware\laser\laser.py", line 205, in get_laser_power
    return float(self.send_query("?P"))
  File "C:\Users\ctcheung\OneDrive - The University of Chicago\UChicago Postgrad\Research\High Magnetic Field NV\program\diamonddash\hardware\laser\laser.py", line 48, in send_query
    return super().send(input).encode('ASCII')
AttributeError: 'int' object has no attribute 'encode'
2023-04-10 19:28:47.243 [   DEBUG] (         protocol.py: 331) Exception caught
Traceback (most recent call last):
  File "C:\Users\ctcheung\.conda\envs\hfnvenv\lib\site-packages\rpyc\core\protocol.py", line 324, in _dispatch_request
    res = self._HANDLERS[handler](self, *args)
  File "C:\Users\ctcheung\.conda\envs\hfnvenv\lib\site-packages\rpyc\core\protocol.py", line 609, in _handle_call
    return obj(*args, **dict(kwargs))
  File "C:\Users\ctcheung\OneDrive - The University of Chicago\UChicago Postgrad\Research\High Magnetic Field NV\program\diamonddash\hardware\laser\laser.py", line 205, in get_laser_power
    return float(self.send_query("?P"))
  File "C:\Users\ctcheung\OneDrive - The University of Chicago\UChicago Postgrad\Research\High Magnetic Field NV\program\diamonddash\hardware\laser\laser.py", line 48, in send_query
    return super().send(input).encode('ASCII')
AttributeError: 'int' object has no attribute 'encode'
2023-04-10 19:28:47.418 [    INFO] (            laser.py: 111) Laser emission is OFF
2023-04-10 19:28:47.419 [ WARNING] (            laser.py:  43) Failed to set command 'L=0'
2023-04-10 19:28:47.420 [ WARNING] (            laser.py:  44) Response from Device :'-1'
2023-04-10 19:28:47.749 [   DEBUG] (         protocol.py: 331) Exception caught
Traceback (most recent call last):
  File "C:\Users\ctcheung\.conda\envs\hfnvenv\lib\site-packages\rpyc\core\protocol.py", line 324, in _dispatch_request
    res = self._HANDLERS[handler](self, *args)
  File "C:\Users\ctcheung\.conda\envs\hfnvenv\lib\site-packages\rpyc\core\protocol.py", line 609, in _handle_call
    return obj(*args, **dict(kwargs))
  File "C:\Users\ctcheung\OneDrive - The University of Chicago\UChicago Postgrad\Research\High Magnetic Field NV\program\diamonddash\hardware\laser\laser.py", line 205, in get_laser_power
    return float(self.send_query("?P"))
  File "C:\Users\ctcheung\OneDrive - The University of Chicago\UChicago Postgrad\Research\High Magnetic Field NV\program\diamonddash\hardware\laser\laser.py", line 48, in send_query
    return super().send(input).encode('ASCII')
AttributeError: 'int' object has no attribute 'encode'
2023-04-10 19:28:48.026 [    INFO] (            laser.py: 108) Laser emission is ON
2023-04-10 19:28:48.027 [ WARNING] (            laser.py:  43) Failed to set command 'L=1'
2023-04-10 19:28:48.027 [ WARNING] (            laser.py:  44) Response from Device :'-1'
2023-04-10 19:28:48.246 [   DEBUG] (         protocol.py: 331) Exception caught
Traceback (most recent call last):
  File "C:\Users\ctcheung\.conda\envs\hfnvenv\lib\site-packages\rpyc\core\protocol.py", line 324, in _dispatch_request
    res = self._HANDLERS[handler](self, *args)
  File "C:\Users\ctcheung\.conda\envs\hfnvenv\lib\site-packages\rpyc\core\protocol.py", line 609, in _handle_call
    return obj(*args, **dict(kwargs))
  File "C:\Users\ctcheung\OneDrive - The University of Chicago\UChicago Postgrad\Research\High Magnetic Field NV\program\diamonddash\hardware\laser\laser.py", line 205, in get_laser_power
    return float(self.send_query("?P"))
  File "C:\Users\ctcheung\OneDrive - The University of Chicago\UChicago Postgrad\Research\High Magnetic Field NV\program\diamonddash\hardware\laser\laser.py", line 48, in send_query
    return super().send(input).encode('ASCII')
AttributeError: 'int' object has no attribute 'encode'
2023-04-10 19:28:48.758 [   DEBUG] (         protocol.py: 331) Exception caught
Traceback (most recent call last):
  File "C:\Users\ctcheung\.conda\envs\hfnvenv\lib\site-packages\rpyc\core\protocol.py", line 324, in _dispatch_request
    res = self._HANDLERS[handler](self, *args)
  File "C:\Users\ctcheung\.conda\envs\hfnvenv\lib\site-packages\rpyc\core\protocol.py", line 609, in _handle_call
    return obj(*args, **dict(kwargs))
  File "C:\Users\ctcheung\OneDrive - The University of Chicago\UChicago Postgrad\Research\High Magnetic Field NV\program\diamonddash\hardware\laser\laser.py", line 205, in get_laser_power
    return float(self.send_query("?P"))
  File "C:\Users\ctcheung\OneDrive - The University of Chicago\UChicago Postgrad\Research\High Magnetic Field NV\program\diamonddash\hardware\laser\laser.py", line 48, in send_query
    return super().send(input).encode('ASCII')
AttributeError: 'int' object has no attribute 'encode'
2023-04-10 19:28:49.250 [   DEBUG] (         protocol.py: 331) Exception caught
Traceback (most recent call last):
  File "C:\Users\ctcheung\.conda\envs\hfnvenv\lib\site-packages\rpyc\core\protocol.py", line 324, in _dispatch_request
    res = self._HANDLERS[handler](self, *args)
  File "C:\Users\ctcheung\.conda\envs\hfnvenv\lib\site-packages\rpyc\core\protocol.py", line 609, in _handle_call
    return obj(*args, **dict(kwargs))
  File "C:\Users\ctcheung\OneDrive - The University of Chicago\UChicago Postgrad\Research\High Magnetic Field NV\program\diamonddash\hardware\laser\laser.py", line 205, in get_laser_power
    return float(self.send_query("?P"))
  File "C:\Users\ctcheung\OneDrive - The University of Chicago\UChicago Postgrad\Research\High Magnetic Field NV\program\diamonddash\hardware\laser\laser.py", line 48, in send_query
    return super().send(input).encode('ASCII')
AttributeError: 'int' object has no attribute 'encode'
2023-04-10 19:28:49.751 [   DEBUG] (         protocol.py: 331) Exception caught
Traceback (most recent call last):
  File "C:\Users\ctcheung\.conda\envs\hfnvenv\lib\site-packages\rpyc\core\protocol.py", line 324, in _dispatch_request
    res = self._HANDLERS[handler](self, *args)
  File "C:\Users\ctcheung\.conda\envs\hfnvenv\lib\site-packages\rpyc\core\protocol.py", line 609, in _handle_call
    return obj(*args, **dict(kwargs))
  File "C:\Users\ctcheung\OneDrive - The University of Chicago\UChicago Postgrad\Research\High Magnetic Field NV\program\diamonddash\hardware\laser\laser.py", line 205, in get_laser_power
    return float(self.send_query("?P"))
  File "C:\Users\ctcheung\OneDrive - The University of Chicago\UChicago Postgrad\Research\High Magnetic Field NV\program\diamonddash\hardware\laser\laser.py", line 48, in send_query
    return super().send(input).encode('ASCII')
AttributeError: 'int' object has no attribute 'encode'
2023-04-10 19:28:50.258 [   DEBUG] (         protocol.py: 331) Exception caught
Traceback (most recent call last):
  File "C:\Users\ctcheung\.conda\envs\hfnvenv\lib\site-packages\rpyc\core\protocol.py", line 324, in _dispatch_request
    res = self._HANDLERS[handler](self, *args)
  File "C:\Users\ctcheung\.conda\envs\hfnvenv\lib\site-packages\rpyc\core\protocol.py", line 609, in _handle_call
    return obj(*args, **dict(kwargs))
  File "C:\Users\ctcheung\OneDrive - The University of Chicago\UChicago Postgrad\Research\High Magnetic Field NV\program\diamonddash\hardware\laser\laser.py", line 205, in get_laser_power
    return float(self.send_query("?P"))
  File "C:\Users\ctcheung\OneDrive - The University of Chicago\UChicago Postgrad\Research\High Magnetic Field NV\program\diamonddash\hardware\laser\laser.py", line 48, in send_query
    return super().send(input).encode('ASCII')
AttributeError: 'int' object has no attribute 'encode'
2023-04-10 19:28:50.741 [   DEBUG] (         protocol.py: 331) Exception caught
Traceback (most recent call last):
  File "C:\Users\ctcheung\.conda\envs\hfnvenv\lib\site-packages\rpyc\core\protocol.py", line 324, in _dispatch_request
    res = self._HANDLERS[handler](self, *args)
  File "C:\Users\ctcheung\.conda\envs\hfnvenv\lib\site-packages\rpyc\core\protocol.py", line 609, in _handle_call
    return obj(*args, **dict(kwargs))
  File "C:\Users\ctcheung\OneDrive - The University of Chicago\UChicago Postgrad\Research\High Magnetic Field NV\program\diamonddash\hardware\laser\laser.py", line 205, in get_laser_power
    return float(self.send_query("?P"))
  File "C:\Users\ctcheung\OneDrive - The University of Chicago\UChicago Postgrad\Research\High Magnetic Field NV\program\diamonddash\hardware\laser\laser.py", line 48, in send_query
    return super().send(input).encode('ASCII')
AttributeError: 'int' object has no attribute 'encode'
2023-04-10 19:28:51.255 [   DEBUG] (         protocol.py: 331) Exception caught
Traceback (most recent call last):
  File "C:\Users\ctcheung\.conda\envs\hfnvenv\lib\site-packages\rpyc\core\protocol.py", line 324, in _dispatch_request
    res = self._HANDLERS[handler](self, *args)
  File "C:\Users\ctcheung\.conda\envs\hfnvenv\lib\site-packages\rpyc\core\protocol.py", line 609, in _handle_call
    return obj(*args, **dict(kwargs))
  File "C:\Users\ctcheung\OneDrive - The University of Chicago\UChicago Postgrad\Research\High Magnetic Field NV\program\diamonddash\hardware\laser\laser.py", line 205, in get_laser_power
    return float(self.send_query("?P"))
  File "C:\Users\ctcheung\OneDrive - The University of Chicago\UChicago Postgrad\Research\High Magnetic Field NV\program\diamonddash\hardware\laser\laser.py", line 48, in send_query
    return super().send(input).encode('ASCII')
AttributeError: 'int' object has no attribute 'encode'
2023-04-10 19:28:51.749 [   DEBUG] (         protocol.py: 331) Exception caught
Traceback (most recent call last):
  File "C:\Users\ctcheung\.conda\envs\hfnvenv\lib\site-packages\rpyc\core\protocol.py", line 324, in _dispatch_request
    res = self._HANDLERS[handler](self, *args)
  File "C:\Users\ctcheung\.conda\envs\hfnvenv\lib\site-packages\rpyc\core\protocol.py", line 609, in _handle_call
    return obj(*args, **dict(kwargs))
  File "C:\Users\ctcheung\OneDrive - The University of Chicago\UChicago Postgrad\Research\High Magnetic Field NV\program\diamonddash\hardware\laser\laser.py", line 205, in get_laser_power
    return float(self.send_query("?P"))
  File "C:\Users\ctcheung\OneDrive - The University of Chicago\UChicago Postgrad\Research\High Magnetic Field NV\program\diamonddash\hardware\laser\laser.py", line 48, in send_query
    return super().send(input).encode('ASCII')
AttributeError: 'int' object has no attribute 'encode'
2023-04-10 19:28:52.247 [   DEBUG] (         protocol.py: 331) Exception caught
Traceback (most recent call last):
  File "C:\Users\ctcheung\.conda\envs\hfnvenv\lib\site-packages\rpyc\core\protocol.py", line 324, in _dispatch_request
    res = self._HANDLERS[handler](self, *args)
  File "C:\Users\ctcheung\.conda\envs\hfnvenv\lib\site-packages\rpyc\core\protocol.py", line 609, in _handle_call
    return obj(*args, **dict(kwargs))
  File "C:\Users\ctcheung\OneDrive - The University of Chicago\UChicago Postgrad\Research\High Magnetic Field NV\program\diamonddash\hardware\laser\laser.py", line 205, in get_laser_power
    return float(self.send_query("?P"))
  File "C:\Users\ctcheung\OneDrive - The University of Chicago\UChicago Postgrad\Research\High Magnetic Field NV\program\diamonddash\hardware\laser\laser.py", line 48, in send_query
    return super().send(input).encode('ASCII')
AttributeError: 'int' object has no attribute 'encode'
2023-04-10 19:28:52.741 [   DEBUG] (         protocol.py: 331) Exception caught
Traceback (most recent call last):
  File "C:\Users\ctcheung\.conda\envs\hfnvenv\lib\site-packages\rpyc\core\protocol.py", line 324, in _dispatch_request
    res = self._HANDLERS[handler](self, *args)
  File "C:\Users\ctcheung\.conda\envs\hfnvenv\lib\site-packages\rpyc\core\protocol.py", line 609, in _handle_call
    return obj(*args, **dict(kwargs))
  File "C:\Users\ctcheung\OneDrive - The University of Chicago\UChicago Postgrad\Research\High Magnetic Field NV\program\diamonddash\hardware\laser\laser.py", line 205, in get_laser_power
    return float(self.send_query("?P"))
  File "C:\Users\ctcheung\OneDrive - The University of Chicago\UChicago Postgrad\Research\High Magnetic Field NV\program\diamonddash\hardware\laser\laser.py", line 48, in send_query
    return super().send(input).encode('ASCII')
AttributeError: 'int' object has no attribute 'encode'
2023-04-10 19:28:53.244 [   DEBUG] (         protocol.py: 331) Exception caught
Traceback (most recent call last):
  File "C:\Users\ctcheung\.conda\envs\hfnvenv\lib\site-packages\rpyc\core\protocol.py", line 324, in _dispatch_request
    res = self._HANDLERS[handler](self, *args)
  File "C:\Users\ctcheung\.conda\envs\hfnvenv\lib\site-packages\rpyc\core\protocol.py", line 609, in _handle_call
    return obj(*args, **dict(kwargs))
  File "C:\Users\ctcheung\OneDrive - The University of Chicago\UChicago Postgrad\Research\High Magnetic Field NV\program\diamonddash\hardware\laser\laser.py", line 205, in get_laser_power
    return float(self.send_query("?P"))
  File "C:\Users\ctcheung\OneDrive - The University of Chicago\UChicago Postgrad\Research\High Magnetic Field NV\program\diamonddash\hardware\laser\laser.py", line 48, in send_query
    return super().send(input).encode('ASCII')
AttributeError: 'int' object has no attribute 'encode'
2023-04-10 19:28:53.750 [   DEBUG] (         protocol.py: 331) Exception caught
Traceback (most recent call last):
  File "C:\Users\ctcheung\.conda\envs\hfnvenv\lib\site-packages\rpyc\core\protocol.py", line 324, in _dispatch_request
    res = self._HANDLERS[handler](self, *args)
  File "C:\Users\ctcheung\.conda\envs\hfnvenv\lib\site-packages\rpyc\core\protocol.py", line 609, in _handle_call
    return obj(*args, **dict(kwargs))
  File "C:\Users\ctcheung\OneDrive - The University of Chicago\UChicago Postgrad\Research\High Magnetic Field NV\program\diamonddash\hardware\laser\laser.py", line 205, in get_laser_power
    return float(self.send_query("?P"))
  File "C:\Users\ctcheung\OneDrive - The University of Chicago\UChicago Postgrad\Research\High Magnetic Field NV\program\diamonddash\hardware\laser\laser.py", line 48, in send_query
    return super().send(input).encode('ASCII')
AttributeError: 'int' object has no attribute 'encode'
2023-04-10 19:28:54.244 [   DEBUG] (         protocol.py: 331) Exception caught
Traceback (most recent call last):
  File "C:\Users\ctcheung\.conda\envs\hfnvenv\lib\site-packages\rpyc\core\protocol.py", line 324, in _dispatch_request
    res = self._HANDLERS[handler](self, *args)
  File "C:\Users\ctcheung\.conda\envs\hfnvenv\lib\site-packages\rpyc\core\protocol.py", line 609, in _handle_call
    return obj(*args, **dict(kwargs))
  File "C:\Users\ctcheung\OneDrive - The University of Chicago\UChicago Postgrad\Research\High Magnetic Field NV\program\diamonddash\hardware\laser\laser.py", line 205, in get_laser_power
    return float(self.send_query("?P"))
  File "C:\Users\ctcheung\OneDrive - The University of Chicago\UChicago Postgrad\Research\High Magnetic Field NV\program\diamonddash\hardware\laser\laser.py", line 48, in send_query
    return super().send(input).encode('ASCII')
AttributeError: 'int' object has no attribute 'encode'
2023-04-10 19:28:54.751 [   DEBUG] (         protocol.py: 331) Exception caught
Traceback (most recent call last):
  File "C:\Users\ctcheung\.conda\envs\hfnvenv\lib\site-packages\rpyc\core\protocol.py", line 324, in _dispatch_request
    res = self._HANDLERS[handler](self, *args)
  File "C:\Users\ctcheung\.conda\envs\hfnvenv\lib\site-packages\rpyc\core\protocol.py", line 609, in _handle_call
    return obj(*args, **dict(kwargs))
  File "C:\Users\ctcheung\OneDrive - The University of Chicago\UChicago Postgrad\Research\High Magnetic Field NV\program\diamonddash\hardware\laser\laser.py", line 205, in get_laser_power
    return float(self.send_query("?P"))
  File "C:\Users\ctcheung\OneDrive - The University of Chicago\UChicago Postgrad\Research\High Magnetic Field NV\program\diamonddash\hardware\laser\laser.py", line 48, in send_query
    return super().send(input).encode('ASCII')
AttributeError: 'int' object has no attribute 'encode'
2023-04-10 19:28:55.245 [   DEBUG] (         protocol.py: 331) Exception caught
Traceback (most recent call last):
  File "C:\Users\ctcheung\.conda\envs\hfnvenv\lib\site-packages\rpyc\core\protocol.py", line 324, in _dispatch_request
    res = self._HANDLERS[handler](self, *args)
  File "C:\Users\ctcheung\.conda\envs\hfnvenv\lib\site-packages\rpyc\core\protocol.py", line 609, in _handle_call
    return obj(*args, **dict(kwargs))
  File "C:\Users\ctcheung\OneDrive - The University of Chicago\UChicago Postgrad\Research\High Magnetic Field NV\program\diamonddash\hardware\laser\laser.py", line 205, in get_laser_power
    return float(self.send_query("?P"))
  File "C:\Users\ctcheung\OneDrive - The University of Chicago\UChicago Postgrad\Research\High Magnetic Field NV\program\diamonddash\hardware\laser\laser.py", line 48, in send_query
    return super().send(input).encode('ASCII')
AttributeError: 'int' object has no attribute 'encode'
2023-04-10 19:28:55.747 [   DEBUG] (         protocol.py: 331) Exception caught
Traceback (most recent call last):
  File "C:\Users\ctcheung\.conda\envs\hfnvenv\lib\site-packages\rpyc\core\protocol.py", line 324, in _dispatch_request
    res = self._HANDLERS[handler](self, *args)
  File "C:\Users\ctcheung\.conda\envs\hfnvenv\lib\site-packages\rpyc\core\protocol.py", line 609, in _handle_call
    return obj(*args, **dict(kwargs))
  File "C:\Users\ctcheung\OneDrive - The University of Chicago\UChicago Postgrad\Research\High Magnetic Field NV\program\diamonddash\hardware\laser\laser.py", line 205, in get_laser_power
    return float(self.send_query("?P"))
  File "C:\Users\ctcheung\OneDrive - The University of Chicago\UChicago Postgrad\Research\High Magnetic Field NV\program\diamonddash\hardware\laser\laser.py", line 48, in send_query
    return super().send(input).encode('ASCII')
AttributeError: 'int' object has no attribute 'encode'
2023-04-10 19:28:56.241 [   DEBUG] (         protocol.py: 331) Exception caught
Traceback (most recent call last):
  File "C:\Users\ctcheung\.conda\envs\hfnvenv\lib\site-packages\rpyc\core\protocol.py", line 324, in _dispatch_request
    res = self._HANDLERS[handler](self, *args)
  File "C:\Users\ctcheung\.conda\envs\hfnvenv\lib\site-packages\rpyc\core\protocol.py", line 609, in _handle_call
    return obj(*args, **dict(kwargs))
  File "C:\Users\ctcheung\OneDrive - The University of Chicago\UChicago Postgrad\Research\High Magnetic Field NV\program\diamonddash\hardware\laser\laser.py", line 205, in get_laser_power
    return float(self.send_query("?P"))
  File "C:\Users\ctcheung\OneDrive - The University of Chicago\UChicago Postgrad\Research\High Magnetic Field NV\program\diamonddash\hardware\laser\laser.py", line 48, in send_query
    return super().send(input).encode('ASCII')
AttributeError: 'int' object has no attribute 'encode'
2023-04-10 19:28:56.749 [   DEBUG] (         protocol.py: 331) Exception caught
Traceback (most recent call last):
  File "C:\Users\ctcheung\.conda\envs\hfnvenv\lib\site-packages\rpyc\core\protocol.py", line 324, in _dispatch_request
    res = self._HANDLERS[handler](self, *args)
  File "C:\Users\ctcheung\.conda\envs\hfnvenv\lib\site-packages\rpyc\core\protocol.py", line 609, in _handle_call
    return obj(*args, **dict(kwargs))
  File "C:\Users\ctcheung\OneDrive - The University of Chicago\UChicago Postgrad\Research\High Magnetic Field NV\program\diamonddash\hardware\laser\laser.py", line 205, in get_laser_power
    return float(self.send_query("?P"))
  File "C:\Users\ctcheung\OneDrive - The University of Chicago\UChicago Postgrad\Research\High Magnetic Field NV\program\diamonddash\hardware\laser\laser.py", line 48, in send_query
    return super().send(input).encode('ASCII')
AttributeError: 'int' object has no attribute 'encode'
2023-04-10 19:28:57.240 [   DEBUG] (         protocol.py: 331) Exception caught
Traceback (most recent call last):
  File "C:\Users\ctcheung\.conda\envs\hfnvenv\lib\site-packages\rpyc\core\protocol.py", line 324, in _dispatch_request
    res = self._HANDLERS[handler](self, *args)
  File "C:\Users\ctcheung\.conda\envs\hfnvenv\lib\site-packages\rpyc\core\protocol.py", line 609, in _handle_call
    return obj(*args, **dict(kwargs))
  File "C:\Users\ctcheung\OneDrive - The University of Chicago\UChicago Postgrad\Research\High Magnetic Field NV\program\diamonddash\hardware\laser\laser.py", line 205, in get_laser_power
    return float(self.send_query("?P"))
  File "C:\Users\ctcheung\OneDrive - The University of Chicago\UChicago Postgrad\Research\High Magnetic Field NV\program\diamonddash\hardware\laser\laser.py", line 48, in send_query
    return super().send(input).encode('ASCII')
AttributeError: 'int' object has no attribute 'encode'
2023-04-10 19:28:57.741 [   DEBUG] (         protocol.py: 331) Exception caught
Traceback (most recent call last):
  File "C:\Users\ctcheung\.conda\envs\hfnvenv\lib\site-packages\rpyc\core\protocol.py", line 324, in _dispatch_request
    res = self._HANDLERS[handler](self, *args)
  File "C:\Users\ctcheung\.conda\envs\hfnvenv\lib\site-packages\rpyc\core\protocol.py", line 609, in _handle_call
    return obj(*args, **dict(kwargs))
  File "C:\Users\ctcheung\OneDrive - The University of Chicago\UChicago Postgrad\Research\High Magnetic Field NV\program\diamonddash\hardware\laser\laser.py", line 205, in get_laser_power
    return float(self.send_query("?P"))
  File "C:\Users\ctcheung\OneDrive - The University of Chicago\UChicago Postgrad\Research\High Magnetic Field NV\program\diamonddash\hardware\laser\laser.py", line 48, in send_query
    return super().send(input).encode('ASCII')
AttributeError: 'int' object has no attribute 'encode'
2023-04-10 19:28:59.607 [    INFO] (           inserv.py: 354) client <rpyc.core.protocol.Connection 'conn4' object at 0x0000023EBD501BD0> disconnected
2023-04-10 19:28:59.608 [    INFO] (           server.py: 206) goodbye ('127.0.0.1', 1552)
2023-04-10 19:29:16.635 [    INFO] (          gateway.py: 133) Gateway connected to instrument server at "localhost:42068"
2023-04-10 19:29:16.635 [    INFO] (           server.py: 156) accepted ('127.0.0.1', 8731) with fd 1216
2023-04-10 19:29:16.635 [    INFO] (           server.py: 199) welcome ('127.0.0.1', 8731)
2023-04-10 19:29:16.635 [    INFO] (           inserv.py: 350) client <rpyc.core.protocol.Connection 'conn5' object at 0x0000023EBD503AF0> connected
2023-04-10 19:29:16.645 [   DEBUG] (         protocol.py: 331) Exception caught
Traceback (most recent call last):
  File "C:\Users\ctcheung\.conda\envs\hfnvenv\lib\site-packages\rpyc\core\protocol.py", line 324, in _dispatch_request
    res = self._HANDLERS[handler](self, *args)
  File "C:\Users\ctcheung\.conda\envs\hfnvenv\lib\site-packages\rpyc\core\protocol.py", line 609, in _handle_call
    return obj(*args, **dict(kwargs))
  File "C:\Users\ctcheung\.conda\envs\hfnvenv\lib\site-packages\nspyre\inserv\inserv.py", line 157, in add
    raise InstrumentServerDeviceExistsError(f'device "{name}" already exists')
nspyre.inserv.inserv.InstrumentServerDeviceExistsError: device "drv" already exists
2023-04-10 19:29:16.655 [CRITICAL] (          logging.py:  31) Traceback (most recent call last):
2023-04-10 19:29:16.655 [CRITICAL] (          logging.py:  31)   File "C:\Users\ctcheung\OneDrive - The University of Chicago\UChicago Postgrad\Research\High Magnetic Field NV\program\diamonddash\inserv_dummy.py", line 37, in <module>
2023-04-10 19:29:16.655 [CRITICAL] (          logging.py:  31)     inserv.add('drv', HERE / 'hardware' / 'driver_dummy.py', 'FakeInstrument')
2023-04-10 19:29:16.655 [CRITICAL] (          logging.py:  31)   File "C:\Users\ctcheung\.conda\envs\hfnvenv\lib\site-packages\rpyc\core\netref.py", line 240, in __call__
2023-04-10 19:29:16.665 [CRITICAL] (          logging.py:  31)     return syncreq(_self, consts.HANDLE_CALL, args, kwargs)
2023-04-10 19:29:16.665 [CRITICAL] (          logging.py:  31)   File "C:\Users\ctcheung\.conda\envs\hfnvenv\lib\site-packages\rpyc\core\netref.py", line 63, in syncreq
2023-04-10 19:29:16.665 [CRITICAL] (          logging.py:  31)     return conn.sync_request(handler, proxy, *args)
2023-04-10 19:29:16.665 [CRITICAL] (          logging.py:  31)   File "C:\Users\ctcheung\.conda\envs\hfnvenv\lib\site-packages\rpyc\core\protocol.py", line 490, in sync_request
2023-04-10 19:29:16.665 [CRITICAL] (          logging.py:  31)     return _async_res.value
2023-04-10 19:29:16.665 [CRITICAL] (          logging.py:  31)   File "C:\Users\ctcheung\.conda\envs\hfnvenv\lib\site-packages\rpyc\core\async_.py", line 108, in value
2023-04-10 19:29:16.675 [CRITICAL] (          logging.py:  31)     raise self._obj
2023-04-10 19:29:16.675 [CRITICAL] (          logging.py:  31) rpyc.core.vinegar/nspyre.inserv.inserv._get_exception_class.<locals>.Derived: device "drv" already exists
2023-04-10 19:29:16.675 [CRITICAL] (          logging.py:  31) 
2023-04-10 19:29:16.675 [CRITICAL] (          logging.py:  31) ========= Remote Traceback (1) =========
2023-04-10 19:29:16.675 [CRITICAL] (          logging.py:  31) Traceback (most recent call last):
2023-04-10 19:29:16.675 [CRITICAL] (          logging.py:  31)   File "C:\Users\ctcheung\.conda\envs\hfnvenv\lib\site-packages\rpyc\core\protocol.py", line 324, in _dispatch_request
2023-04-10 19:29:16.675 [CRITICAL] (          logging.py:  31)     res = self._HANDLERS[handler](self, *args)
2023-04-10 19:29:16.675 [CRITICAL] (          logging.py:  31)   File "C:\Users\ctcheung\.conda\envs\hfnvenv\lib\site-packages\rpyc\core\protocol.py", line 609, in _handle_call
2023-04-10 19:29:16.675 [CRITICAL] (          logging.py:  31)     return obj(*args, **dict(kwargs))
2023-04-10 19:29:16.675 [CRITICAL] (          logging.py:  31)   File "C:\Users\ctcheung\.conda\envs\hfnvenv\lib\site-packages\nspyre\inserv\inserv.py", line 157, in add
2023-04-10 19:29:16.675 [CRITICAL] (          logging.py:  31)     raise InstrumentServerDeviceExistsError(f'device "{name}" already exists')
2023-04-10 19:29:16.675 [CRITICAL] (          logging.py:  31) nspyre.inserv.inserv.InstrumentServerDeviceExistsError: device "drv" already exists
2023-04-10 19:29:16.675 [CRITICAL] (          logging.py:  31) 
2023-04-10 19:29:16.698 [    INFO] (           inserv.py: 354) client <rpyc.core.protocol.Connection 'conn5' object at 0x0000023EBD503AF0> disconnected
2023-04-10 19:29:16.698 [    INFO] (           server.py: 206) goodbye ('127.0.0.1', 8731)
2023-04-10 19:29:16.963 [    INFO] (           server.py: 156) accepted ('127.0.0.1', 8732) with fd 1528
2023-04-10 19:29:16.963 [    INFO] (           server.py: 199) welcome ('127.0.0.1', 8732)
2023-04-10 19:29:16.963 [    INFO] (           inserv.py: 350) client <rpyc.core.protocol.Connection 'conn6' object at 0x0000023EBD60D6C0> connected
2023-04-10 19:29:17.967 [   DEBUG] (         protocol.py: 331) Exception caught
Traceback (most recent call last):
  File "C:\Users\ctcheung\.conda\envs\hfnvenv\lib\site-packages\rpyc\core\protocol.py", line 324, in _dispatch_request
    res = self._HANDLERS[handler](self, *args)
  File "C:\Users\ctcheung\.conda\envs\hfnvenv\lib\site-packages\rpyc\core\protocol.py", line 609, in _handle_call
    return obj(*args, **dict(kwargs))
  File "C:\Users\ctcheung\OneDrive - The University of Chicago\UChicago Postgrad\Research\High Magnetic Field NV\program\diamonddash\hardware\laser\laser.py", line 201, in get_max_laser_power
    return float(self.send_query("?MAXLP"))
  File "C:\Users\ctcheung\OneDrive - The University of Chicago\UChicago Postgrad\Research\High Magnetic Field NV\program\diamonddash\hardware\laser\laser.py", line 48, in send_query
    return super().send(input).encode('ASCII')
AttributeError: 'int' object has no attribute 'encode'
2023-04-10 19:29:18.974 [    INFO] (           server.py: 156) accepted ('127.0.0.1', 8733) with fd 1884
2023-04-10 19:29:18.974 [    INFO] (           server.py: 199) welcome ('127.0.0.1', 8733)
2023-04-10 19:29:18.974 [    INFO] (           inserv.py: 350) client <rpyc.core.protocol.Connection 'conn7' object at 0x0000023EBD60D9F0> connected
2023-04-10 19:29:19.024 [    INFO] (           inserv.py: 354) client <rpyc.core.protocol.Connection 'conn6' object at 0x0000023EBD60D6C0> disconnected
2023-04-10 19:29:19.024 [    INFO] (           server.py: 206) goodbye ('127.0.0.1', 8732)
2023-04-10 19:29:27.614 [    INFO] (           server.py: 156) accepted ('127.0.0.1', 8770) with fd 1920
2023-04-10 19:29:27.614 [    INFO] (           inserv.py: 354) client <rpyc.core.protocol.Connection 'conn7' object at 0x0000023EBD60D9F0> disconnected
2023-04-10 19:29:27.615 [    INFO] (           server.py: 199) welcome ('127.0.0.1', 8770)
2023-04-10 19:29:27.615 [    INFO] (           server.py: 206) goodbye ('127.0.0.1', 8733)
2023-04-10 19:29:27.616 [    INFO] (           inserv.py: 350) client <rpyc.core.protocol.Connection 'conn8' object at 0x0000023EBD60DB10> connected
2023-04-10 19:29:27.626 [   DEBUG] (         protocol.py: 331) Exception caught
Traceback (most recent call last):
  File "C:\Users\ctcheung\.conda\envs\hfnvenv\lib\site-packages\rpyc\core\protocol.py", line 324, in _dispatch_request
    res = self._HANDLERS[handler](self, *args)
  File "C:\Users\ctcheung\.conda\envs\hfnvenv\lib\site-packages\rpyc\core\protocol.py", line 609, in _handle_call
    return obj(*args, **dict(kwargs))
  File "C:\Users\ctcheung\OneDrive - The University of Chicago\UChicago Postgrad\Research\High Magnetic Field NV\program\diamonddash\hardware\laser\laser.py", line 263, in is_laser_on
    return self.get_laser_emission_activation()
  File "C:\Users\ctcheung\OneDrive - The University of Chicago\UChicago Postgrad\Research\High Magnetic Field NV\program\diamonddash\hardware\laser\laser.py", line 192, in get_laser_emission_activation
    rep = int(self.send_query("?L"))
  File "C:\Users\ctcheung\OneDrive - The University of Chicago\UChicago Postgrad\Research\High Magnetic Field NV\program\diamonddash\hardware\laser\laser.py", line 48, in send_query
    return super().send(input).encode('ASCII')
AttributeError: 'int' object has no attribute 'encode'
2023-04-10 19:29:28.164 [   DEBUG] (         protocol.py: 331) Exception caught
Traceback (most recent call last):
  File "C:\Users\ctcheung\.conda\envs\hfnvenv\lib\site-packages\rpyc\core\protocol.py", line 324, in _dispatch_request
    res = self._HANDLERS[handler](self, *args)
  File "C:\Users\ctcheung\.conda\envs\hfnvenv\lib\site-packages\rpyc\core\protocol.py", line 609, in _handle_call
    return obj(*args, **dict(kwargs))
  File "C:\Users\ctcheung\OneDrive - The University of Chicago\UChicago Postgrad\Research\High Magnetic Field NV\program\diamonddash\hardware\laser\laser.py", line 48, in send_query
    return super().send(input).encode('ASCII')
AttributeError: 'int' object has no attribute 'encode'
2023-04-10 19:29:28.173 [   DEBUG] (         protocol.py: 331) Exception caught
Traceback (most recent call last):
  File "C:\Users\ctcheung\.conda\envs\hfnvenv\lib\site-packages\rpyc\core\protocol.py", line 324, in _dispatch_request
    res = self._HANDLERS[handler](self, *args)
  File "C:\Users\ctcheung\.conda\envs\hfnvenv\lib\site-packages\rpyc\core\protocol.py", line 609, in _handle_call
    return obj(*args, **dict(kwargs))
  File "C:\Users\ctcheung\OneDrive - The University of Chicago\UChicago Postgrad\Research\High Magnetic Field NV\program\diamonddash\hardware\laser\laser.py", line 205, in get_laser_power
    return float(self.send_query("?P"))
  File "C:\Users\ctcheung\OneDrive - The University of Chicago\UChicago Postgrad\Research\High Magnetic Field NV\program\diamonddash\hardware\laser\laser.py", line 48, in send_query
    return super().send(input).encode('ASCII')
AttributeError: 'int' object has no attribute 'encode'
2023-04-10 19:29:28.604 [   DEBUG] (         protocol.py: 331) Exception caught
Traceback (most recent call last):
  File "C:\Users\ctcheung\.conda\envs\hfnvenv\lib\site-packages\rpyc\core\protocol.py", line 324, in _dispatch_request
    res = self._HANDLERS[handler](self, *args)
  File "C:\Users\ctcheung\.conda\envs\hfnvenv\lib\site-packages\rpyc\core\protocol.py", line 609, in _handle_call
    return obj(*args, **dict(kwargs))
  File "C:\Users\ctcheung\OneDrive - The University of Chicago\UChicago Postgrad\Research\High Magnetic Field NV\program\diamonddash\hardware\laser\laser.py", line 205, in get_laser_power
    return float(self.send_query("?P"))
  File "C:\Users\ctcheung\OneDrive - The University of Chicago\UChicago Postgrad\Research\High Magnetic Field NV\program\diamonddash\hardware\laser\laser.py", line 48, in send_query
    return super().send(input).encode('ASCII')
AttributeError: 'int' object has no attribute 'encode'
2023-04-10 19:29:29.108 [   DEBUG] (         protocol.py: 331) Exception caught
Traceback (most recent call last):
  File "C:\Users\ctcheung\.conda\envs\hfnvenv\lib\site-packages\rpyc\core\protocol.py", line 324, in _dispatch_request
    res = self._HANDLERS[handler](self, *args)
  File "C:\Users\ctcheung\.conda\envs\hfnvenv\lib\site-packages\rpyc\core\protocol.py", line 609, in _handle_call
    return obj(*args, **dict(kwargs))
  File "C:\Users\ctcheung\OneDrive - The University of Chicago\UChicago Postgrad\Research\High Magnetic Field NV\program\diamonddash\hardware\laser\laser.py", line 205, in get_laser_power
    return float(self.send_query("?P"))
  File "C:\Users\ctcheung\OneDrive - The University of Chicago\UChicago Postgrad\Research\High Magnetic Field NV\program\diamonddash\hardware\laser\laser.py", line 48, in send_query
    return super().send(input).encode('ASCII')
AttributeError: 'int' object has no attribute 'encode'
2023-04-10 19:29:29.607 [   DEBUG] (         protocol.py: 331) Exception caught
Traceback (most recent call last):
  File "C:\Users\ctcheung\.conda\envs\hfnvenv\lib\site-packages\rpyc\core\protocol.py", line 324, in _dispatch_request
    res = self._HANDLERS[handler](self, *args)
  File "C:\Users\ctcheung\.conda\envs\hfnvenv\lib\site-packages\rpyc\core\protocol.py", line 609, in _handle_call
    return obj(*args, **dict(kwargs))
  File "C:\Users\ctcheung\OneDrive - The University of Chicago\UChicago Postgrad\Research\High Magnetic Field NV\program\diamonddash\hardware\laser\laser.py", line 205, in get_laser_power
    return float(self.send_query("?P"))
  File "C:\Users\ctcheung\OneDrive - The University of Chicago\UChicago Postgrad\Research\High Magnetic Field NV\program\diamonddash\hardware\laser\laser.py", line 48, in send_query
    return super().send(input).encode('ASCII')
AttributeError: 'int' object has no attribute 'encode'
2023-04-10 19:29:30.106 [   DEBUG] (         protocol.py: 331) Exception caught
Traceback (most recent call last):
  File "C:\Users\ctcheung\.conda\envs\hfnvenv\lib\site-packages\rpyc\core\protocol.py", line 324, in _dispatch_request
    res = self._HANDLERS[handler](self, *args)
  File "C:\Users\ctcheung\.conda\envs\hfnvenv\lib\site-packages\rpyc\core\protocol.py", line 609, in _handle_call
    return obj(*args, **dict(kwargs))
  File "C:\Users\ctcheung\OneDrive - The University of Chicago\UChicago Postgrad\Research\High Magnetic Field NV\program\diamonddash\hardware\laser\laser.py", line 205, in get_laser_power
    return float(self.send_query("?P"))
  File "C:\Users\ctcheung\OneDrive - The University of Chicago\UChicago Postgrad\Research\High Magnetic Field NV\program\diamonddash\hardware\laser\laser.py", line 48, in send_query
    return super().send(input).encode('ASCII')
AttributeError: 'int' object has no attribute 'encode'
2023-04-10 19:29:30.613 [   DEBUG] (         protocol.py: 331) Exception caught
Traceback (most recent call last):
  File "C:\Users\ctcheung\.conda\envs\hfnvenv\lib\site-packages\rpyc\core\protocol.py", line 324, in _dispatch_request
    res = self._HANDLERS[handler](self, *args)
  File "C:\Users\ctcheung\.conda\envs\hfnvenv\lib\site-packages\rpyc\core\protocol.py", line 609, in _handle_call
    return obj(*args, **dict(kwargs))
  File "C:\Users\ctcheung\OneDrive - The University of Chicago\UChicago Postgrad\Research\High Magnetic Field NV\program\diamonddash\hardware\laser\laser.py", line 205, in get_laser_power
    return float(self.send_query("?P"))
  File "C:\Users\ctcheung\OneDrive - The University of Chicago\UChicago Postgrad\Research\High Magnetic Field NV\program\diamonddash\hardware\laser\laser.py", line 48, in send_query
    return super().send(input).encode('ASCII')
AttributeError: 'int' object has no attribute 'encode'
2023-04-10 19:29:31.104 [   DEBUG] (         protocol.py: 331) Exception caught
Traceback (most recent call last):
  File "C:\Users\ctcheung\.conda\envs\hfnvenv\lib\site-packages\rpyc\core\protocol.py", line 324, in _dispatch_request
    res = self._HANDLERS[handler](self, *args)
  File "C:\Users\ctcheung\.conda\envs\hfnvenv\lib\site-packages\rpyc\core\protocol.py", line 609, in _handle_call
    return obj(*args, **dict(kwargs))
  File "C:\Users\ctcheung\OneDrive - The University of Chicago\UChicago Postgrad\Research\High Magnetic Field NV\program\diamonddash\hardware\laser\laser.py", line 205, in get_laser_power
    return float(self.send_query("?P"))
  File "C:\Users\ctcheung\OneDrive - The University of Chicago\UChicago Postgrad\Research\High Magnetic Field NV\program\diamonddash\hardware\laser\laser.py", line 48, in send_query
    return super().send(input).encode('ASCII')
AttributeError: 'int' object has no attribute 'encode'
2023-04-10 19:29:31.612 [   DEBUG] (         protocol.py: 331) Exception caught
Traceback (most recent call last):
  File "C:\Users\ctcheung\.conda\envs\hfnvenv\lib\site-packages\rpyc\core\protocol.py", line 324, in _dispatch_request
    res = self._HANDLERS[handler](self, *args)
  File "C:\Users\ctcheung\.conda\envs\hfnvenv\lib\site-packages\rpyc\core\protocol.py", line 609, in _handle_call
    return obj(*args, **dict(kwargs))
  File "C:\Users\ctcheung\OneDrive - The University of Chicago\UChicago Postgrad\Research\High Magnetic Field NV\program\diamonddash\hardware\laser\laser.py", line 205, in get_laser_power
    return float(self.send_query("?P"))
  File "C:\Users\ctcheung\OneDrive - The University of Chicago\UChicago Postgrad\Research\High Magnetic Field NV\program\diamonddash\hardware\laser\laser.py", line 48, in send_query
    return super().send(input).encode('ASCII')
AttributeError: 'int' object has no attribute 'encode'
2023-04-10 19:29:31.942 [    INFO] (            laser.py:  58) Analog control mode set to 'current'
2023-04-10 19:29:31.943 [ WARNING] (            laser.py:  43) Failed to set command 'ACC=1'
2023-04-10 19:29:31.944 [ WARNING] (            laser.py:  44) Response from Device :'-1'
2023-04-10 19:29:32.047 [   DEBUG] (         protocol.py: 331) Exception caught
Traceback (most recent call last):
  File "C:\Users\ctcheung\.conda\envs\hfnvenv\lib\site-packages\rpyc\core\protocol.py", line 324, in _dispatch_request
    res = self._HANDLERS[handler](self, *args)
  File "C:\Users\ctcheung\.conda\envs\hfnvenv\lib\site-packages\rpyc\core\protocol.py", line 609, in _handle_call
    return obj(*args, **dict(kwargs))
  File "C:\Users\ctcheung\OneDrive - The University of Chicago\UChicago Postgrad\Research\High Magnetic Field NV\program\diamonddash\hardware\laser\laser.py", line 156, in get_analog_control_mode
    rep = int(self.send_query("?ACC"))
  File "C:\Users\ctcheung\OneDrive - The University of Chicago\UChicago Postgrad\Research\High Magnetic Field NV\program\diamonddash\hardware\laser\laser.py", line 48, in send_query
    return super().send(input).encode('ASCII')
AttributeError: 'int' object has no attribute 'encode'
2023-04-10 19:29:32.104 [   DEBUG] (         protocol.py: 331) Exception caught
Traceback (most recent call last):
  File "C:\Users\ctcheung\.conda\envs\hfnvenv\lib\site-packages\rpyc\core\protocol.py", line 324, in _dispatch_request
    res = self._HANDLERS[handler](self, *args)
  File "C:\Users\ctcheung\.conda\envs\hfnvenv\lib\site-packages\rpyc\core\protocol.py", line 609, in _handle_call
    return obj(*args, **dict(kwargs))
  File "C:\Users\ctcheung\OneDrive - The University of Chicago\UChicago Postgrad\Research\High Magnetic Field NV\program\diamonddash\hardware\laser\laser.py", line 205, in get_laser_power
    return float(self.send_query("?P"))
  File "C:\Users\ctcheung\OneDrive - The University of Chicago\UChicago Postgrad\Research\High Magnetic Field NV\program\diamonddash\hardware\laser\laser.py", line 48, in send_query
    return super().send(input).encode('ASCII')
AttributeError: 'int' object has no attribute 'encode'
2023-04-10 19:29:32.609 [   DEBUG] (         protocol.py: 331) Exception caught
Traceback (most recent call last):
  File "C:\Users\ctcheung\.conda\envs\hfnvenv\lib\site-packages\rpyc\core\protocol.py", line 324, in _dispatch_request
    res = self._HANDLERS[handler](self, *args)
  File "C:\Users\ctcheung\.conda\envs\hfnvenv\lib\site-packages\rpyc\core\protocol.py", line 609, in _handle_call
    return obj(*args, **dict(kwargs))
  File "C:\Users\ctcheung\OneDrive - The University of Chicago\UChicago Postgrad\Research\High Magnetic Field NV\program\diamonddash\hardware\laser\laser.py", line 205, in get_laser_power
    return float(self.send_query("?P"))
  File "C:\Users\ctcheung\OneDrive - The University of Chicago\UChicago Postgrad\Research\High Magnetic Field NV\program\diamonddash\hardware\laser\laser.py", line 48, in send_query
    return super().send(input).encode('ASCII')
AttributeError: 'int' object has no attribute 'encode'
2023-04-10 19:29:32.911 [    INFO] (            laser.py:  55) Analog control mode set to 'power'
2023-04-10 19:29:32.912 [ WARNING] (            laser.py:  43) Failed to set command 'ACC=0'
2023-04-10 19:29:32.912 [ WARNING] (            laser.py:  44) Response from Device :'-1'
2023-04-10 19:29:33.015 [   DEBUG] (         protocol.py: 331) Exception caught
Traceback (most recent call last):
  File "C:\Users\ctcheung\.conda\envs\hfnvenv\lib\site-packages\rpyc\core\protocol.py", line 324, in _dispatch_request
    res = self._HANDLERS[handler](self, *args)
  File "C:\Users\ctcheung\.conda\envs\hfnvenv\lib\site-packages\rpyc\core\protocol.py", line 609, in _handle_call
    return obj(*args, **dict(kwargs))
  File "C:\Users\ctcheung\OneDrive - The University of Chicago\UChicago Postgrad\Research\High Magnetic Field NV\program\diamonddash\hardware\laser\laser.py", line 156, in get_analog_control_mode
    rep = int(self.send_query("?ACC"))
  File "C:\Users\ctcheung\OneDrive - The University of Chicago\UChicago Postgrad\Research\High Magnetic Field NV\program\diamonddash\hardware\laser\laser.py", line 48, in send_query
    return super().send(input).encode('ASCII')
AttributeError: 'int' object has no attribute 'encode'
2023-04-10 19:29:33.116 [   DEBUG] (         protocol.py: 331) Exception caught
Traceback (most recent call last):
  File "C:\Users\ctcheung\.conda\envs\hfnvenv\lib\site-packages\rpyc\core\protocol.py", line 324, in _dispatch_request
    res = self._HANDLERS[handler](self, *args)
  File "C:\Users\ctcheung\.conda\envs\hfnvenv\lib\site-packages\rpyc\core\protocol.py", line 609, in _handle_call
    return obj(*args, **dict(kwargs))
  File "C:\Users\ctcheung\OneDrive - The University of Chicago\UChicago Postgrad\Research\High Magnetic Field NV\program\diamonddash\hardware\laser\laser.py", line 205, in get_laser_power
    return float(self.send_query("?P"))
  File "C:\Users\ctcheung\OneDrive - The University of Chicago\UChicago Postgrad\Research\High Magnetic Field NV\program\diamonddash\hardware\laser\laser.py", line 48, in send_query
    return super().send(input).encode('ASCII')
AttributeError: 'int' object has no attribute 'encode'
2023-04-10 19:29:33.609 [   DEBUG] (         protocol.py: 331) Exception caught
Traceback (most recent call last):
  File "C:\Users\ctcheung\.conda\envs\hfnvenv\lib\site-packages\rpyc\core\protocol.py", line 324, in _dispatch_request
    res = self._HANDLERS[handler](self, *args)
  File "C:\Users\ctcheung\.conda\envs\hfnvenv\lib\site-packages\rpyc\core\protocol.py", line 609, in _handle_call
    return obj(*args, **dict(kwargs))
  File "C:\Users\ctcheung\OneDrive - The University of Chicago\UChicago Postgrad\Research\High Magnetic Field NV\program\diamonddash\hardware\laser\laser.py", line 205, in get_laser_power
    return float(self.send_query("?P"))
  File "C:\Users\ctcheung\OneDrive - The University of Chicago\UChicago Postgrad\Research\High Magnetic Field NV\program\diamonddash\hardware\laser\laser.py", line 48, in send_query
    return super().send(input).encode('ASCII')
AttributeError: 'int' object has no attribute 'encode'
2023-04-10 19:29:34.108 [   DEBUG] (         protocol.py: 331) Exception caught
Traceback (most recent call last):
  File "C:\Users\ctcheung\.conda\envs\hfnvenv\lib\site-packages\rpyc\core\protocol.py", line 324, in _dispatch_request
    res = self._HANDLERS[handler](self, *args)
  File "C:\Users\ctcheung\.conda\envs\hfnvenv\lib\site-packages\rpyc\core\protocol.py", line 609, in _handle_call
    return obj(*args, **dict(kwargs))
  File "C:\Users\ctcheung\OneDrive - The University of Chicago\UChicago Postgrad\Research\High Magnetic Field NV\program\diamonddash\hardware\laser\laser.py", line 205, in get_laser_power
    return float(self.send_query("?P"))
  File "C:\Users\ctcheung\OneDrive - The University of Chicago\UChicago Postgrad\Research\High Magnetic Field NV\program\diamonddash\hardware\laser\laser.py", line 48, in send_query
    return super().send(input).encode('ASCII')
AttributeError: 'int' object has no attribute 'encode'
2023-04-10 19:29:34.609 [   DEBUG] (         protocol.py: 331) Exception caught
Traceback (most recent call last):
  File "C:\Users\ctcheung\.conda\envs\hfnvenv\lib\site-packages\rpyc\core\protocol.py", line 324, in _dispatch_request
    res = self._HANDLERS[handler](self, *args)
  File "C:\Users\ctcheung\.conda\envs\hfnvenv\lib\site-packages\rpyc\core\protocol.py", line 609, in _handle_call
    return obj(*args, **dict(kwargs))
  File "C:\Users\ctcheung\OneDrive - The University of Chicago\UChicago Postgrad\Research\High Magnetic Field NV\program\diamonddash\hardware\laser\laser.py", line 205, in get_laser_power
    return float(self.send_query("?P"))
  File "C:\Users\ctcheung\OneDrive - The University of Chicago\UChicago Postgrad\Research\High Magnetic Field NV\program\diamonddash\hardware\laser\laser.py", line 48, in send_query
    return super().send(input).encode('ASCII')
AttributeError: 'int' object has no attribute 'encode'
2023-04-10 19:29:35.109 [   DEBUG] (         protocol.py: 331) Exception caught
Traceback (most recent call last):
  File "C:\Users\ctcheung\.conda\envs\hfnvenv\lib\site-packages\rpyc\core\protocol.py", line 324, in _dispatch_request
    res = self._HANDLERS[handler](self, *args)
  File "C:\Users\ctcheung\.conda\envs\hfnvenv\lib\site-packages\rpyc\core\protocol.py", line 609, in _handle_call
    return obj(*args, **dict(kwargs))
  File "C:\Users\ctcheung\OneDrive - The University of Chicago\UChicago Postgrad\Research\High Magnetic Field NV\program\diamonddash\hardware\laser\laser.py", line 205, in get_laser_power
    return float(self.send_query("?P"))
  File "C:\Users\ctcheung\OneDrive - The University of Chicago\UChicago Postgrad\Research\High Magnetic Field NV\program\diamonddash\hardware\laser\laser.py", line 48, in send_query
    return super().send(input).encode('ASCII')
AttributeError: 'int' object has no attribute 'encode'
2023-04-10 19:29:35.527 [    INFO] (            laser.py: 108) Laser emission is ON
2023-04-10 19:29:35.528 [ WARNING] (            laser.py:  43) Failed to set command 'L=1'
2023-04-10 19:29:35.528 [ WARNING] (            laser.py:  44) Response from Device :'-1'
2023-04-10 19:29:35.605 [   DEBUG] (         protocol.py: 331) Exception caught
Traceback (most recent call last):
  File "C:\Users\ctcheung\.conda\envs\hfnvenv\lib\site-packages\rpyc\core\protocol.py", line 324, in _dispatch_request
    res = self._HANDLERS[handler](self, *args)
  File "C:\Users\ctcheung\.conda\envs\hfnvenv\lib\site-packages\rpyc\core\protocol.py", line 609, in _handle_call
    return obj(*args, **dict(kwargs))
  File "C:\Users\ctcheung\OneDrive - The University of Chicago\UChicago Postgrad\Research\High Magnetic Field NV\program\diamonddash\hardware\laser\laser.py", line 205, in get_laser_power
    return float(self.send_query("?P"))
  File "C:\Users\ctcheung\OneDrive - The University of Chicago\UChicago Postgrad\Research\High Magnetic Field NV\program\diamonddash\hardware\laser\laser.py", line 48, in send_query
    return super().send(input).encode('ASCII')
AttributeError: 'int' object has no attribute 'encode'
2023-04-10 19:29:36.104 [   DEBUG] (         protocol.py: 331) Exception caught
Traceback (most recent call last):
  File "C:\Users\ctcheung\.conda\envs\hfnvenv\lib\site-packages\rpyc\core\protocol.py", line 324, in _dispatch_request
    res = self._HANDLERS[handler](self, *args)
  File "C:\Users\ctcheung\.conda\envs\hfnvenv\lib\site-packages\rpyc\core\protocol.py", line 609, in _handle_call
    return obj(*args, **dict(kwargs))
  File "C:\Users\ctcheung\OneDrive - The University of Chicago\UChicago Postgrad\Research\High Magnetic Field NV\program\diamonddash\hardware\laser\laser.py", line 205, in get_laser_power
    return float(self.send_query("?P"))
  File "C:\Users\ctcheung\OneDrive - The University of Chicago\UChicago Postgrad\Research\High Magnetic Field NV\program\diamonddash\hardware\laser\laser.py", line 48, in send_query
    return super().send(input).encode('ASCII')
AttributeError: 'int' object has no attribute 'encode'
2023-04-10 19:29:36.605 [   DEBUG] (         protocol.py: 331) Exception caught
Traceback (most recent call last):
  File "C:\Users\ctcheung\.conda\envs\hfnvenv\lib\site-packages\rpyc\core\protocol.py", line 324, in _dispatch_request
    res = self._HANDLERS[handler](self, *args)
  File "C:\Users\ctcheung\.conda\envs\hfnvenv\lib\site-packages\rpyc\core\protocol.py", line 609, in _handle_call
    return obj(*args, **dict(kwargs))
  File "C:\Users\ctcheung\OneDrive - The University of Chicago\UChicago Postgrad\Research\High Magnetic Field NV\program\diamonddash\hardware\laser\laser.py", line 205, in get_laser_power
    return float(self.send_query("?P"))
  File "C:\Users\ctcheung\OneDrive - The University of Chicago\UChicago Postgrad\Research\High Magnetic Field NV\program\diamonddash\hardware\laser\laser.py", line 48, in send_query
    return super().send(input).encode('ASCII')
AttributeError: 'int' object has no attribute 'encode'
2023-04-10 19:29:37.111 [   DEBUG] (         protocol.py: 331) Exception caught
Traceback (most recent call last):
  File "C:\Users\ctcheung\.conda\envs\hfnvenv\lib\site-packages\rpyc\core\protocol.py", line 324, in _dispatch_request
    res = self._HANDLERS[handler](self, *args)
  File "C:\Users\ctcheung\.conda\envs\hfnvenv\lib\site-packages\rpyc\core\protocol.py", line 609, in _handle_call
    return obj(*args, **dict(kwargs))
  File "C:\Users\ctcheung\OneDrive - The University of Chicago\UChicago Postgrad\Research\High Magnetic Field NV\program\diamonddash\hardware\laser\laser.py", line 205, in get_laser_power
    return float(self.send_query("?P"))
  File "C:\Users\ctcheung\OneDrive - The University of Chicago\UChicago Postgrad\Research\High Magnetic Field NV\program\diamonddash\hardware\laser\laser.py", line 48, in send_query
    return super().send(input).encode('ASCII')
AttributeError: 'int' object has no attribute 'encode'
2023-04-10 19:29:37.610 [   DEBUG] (         protocol.py: 331) Exception caught
Traceback (most recent call last):
  File "C:\Users\ctcheung\.conda\envs\hfnvenv\lib\site-packages\rpyc\core\protocol.py", line 324, in _dispatch_request
    res = self._HANDLERS[handler](self, *args)
  File "C:\Users\ctcheung\.conda\envs\hfnvenv\lib\site-packages\rpyc\core\protocol.py", line 609, in _handle_call
    return obj(*args, **dict(kwargs))
  File "C:\Users\ctcheung\OneDrive - The University of Chicago\UChicago Postgrad\Research\High Magnetic Field NV\program\diamonddash\hardware\laser\laser.py", line 205, in get_laser_power
    return float(self.send_query("?P"))
  File "C:\Users\ctcheung\OneDrive - The University of Chicago\UChicago Postgrad\Research\High Magnetic Field NV\program\diamonddash\hardware\laser\laser.py", line 48, in send_query
    return super().send(input).encode('ASCII')
AttributeError: 'int' object has no attribute 'encode'
2023-04-10 19:29:38.857 [    INFO] (           inserv.py: 354) client <rpyc.core.protocol.Connection 'conn8' object at 0x0000023EBD60DB10> disconnected
2023-04-10 19:29:38.858 [    INFO] (           server.py: 206) goodbye ('127.0.0.1', 8770)
2023-04-10 19:30:03.173 [   DEBUG] (          gateway.py: 123) Gateway couldn't connect to instrument server at "localhost:42068"- retrying...
2023-04-10 19:30:03.183 [    INFO] (           inserv.py: 286) starting InstrumentServer RPyC server...
2023-04-10 19:30:03.183 [    INFO] (           server.py: 250) server started on [127.0.0.1]:42068
2023-04-10 19:30:03.287 [    INFO] (           inserv.py: 210) added device "drv" with args: () kwargs: {}
2023-04-10 19:30:03.367 [    INFO] (           server.py: 156) accepted ('127.0.0.1', 8799) with fd 892
2023-04-10 19:30:03.367 [    INFO] (           server.py: 199) welcome ('127.0.0.1', 8799)
2023-04-10 19:30:03.367 [    INFO] (           inserv.py: 350) client <rpyc.core.protocol.Connection 'conn1' object at 0x00000234043057B0> connected
2023-04-10 19:30:03.783 [    INFO] (           inserv.py: 210) added device "laser" with args: ('LAS-09434',) kwargs: {}
2023-04-10 19:30:05.399 [    INFO] (           server.py: 156) accepted ('127.0.0.1', 8804) with fd 1040
2023-04-10 19:30:05.401 [    INFO] (           server.py: 199) welcome ('127.0.0.1', 8804)
2023-04-10 19:30:05.402 [    INFO] (           inserv.py: 350) client <rpyc.core.protocol.Connection 'conn2' object at 0x00000234043061D0> connected
2023-04-10 19:30:05.434 [    INFO] (           inserv.py: 354) client <rpyc.core.protocol.Connection 'conn1' object at 0x00000234043057B0> disconnected
2023-04-10 19:30:05.436 [    INFO] (           server.py: 206) goodbye ('127.0.0.1', 8799)
2023-04-10 19:30:09.837 [    INFO] (           server.py: 156) accepted ('127.0.0.1', 8838) with fd 1068
2023-04-10 19:30:09.837 [    INFO] (           inserv.py: 354) client <rpyc.core.protocol.Connection 'conn2' object at 0x00000234043061D0> disconnected
2023-04-10 19:30:09.838 [    INFO] (           server.py: 206) goodbye ('127.0.0.1', 8804)
2023-04-10 19:30:09.838 [    INFO] (           server.py: 199) welcome ('127.0.0.1', 8838)
2023-04-10 19:30:09.839 [    INFO] (           inserv.py: 350) client <rpyc.core.protocol.Connection 'conn3' object at 0x00000234043060B0> connected
2023-04-10 19:30:09.850 [   DEBUG] (         protocol.py: 331) Exception caught
Traceback (most recent call last):
  File "C:\Users\ctcheung\.conda\envs\hfnvenv\lib\site-packages\rpyc\core\protocol.py", line 324, in _dispatch_request
    res = self._HANDLERS[handler](self, *args)
  File "C:\Users\ctcheung\.conda\envs\hfnvenv\lib\site-packages\rpyc\core\protocol.py", line 609, in _handle_call
    return obj(*args, **dict(kwargs))
  File "C:\Users\ctcheung\OneDrive - The University of Chicago\UChicago Postgrad\Research\High Magnetic Field NV\program\diamonddash\hardware\laser\laser.py", line 48, in send_query
    return super().send(input).encode('ASCII')
AttributeError: 'int' object has no attribute 'encode'
2023-04-10 19:30:12.465 [    INFO] (            laser.py: 108) Laser emission is ON
2023-04-10 19:30:12.941 [    INFO] (            laser.py: 111) Laser emission is OFF
2023-04-10 19:30:14.301 [    INFO] (            laser.py:  58) Analog control mode set to 'current'
2023-04-10 19:30:14.909 [    INFO] (            laser.py:  69) Analog modulation set to 'internal'
2023-04-10 19:30:15.389 [    INFO] (            laser.py: 101) Modulation state set to 'modulated'
2023-04-10 19:30:15.891 [    INFO] (            laser.py: 147) Digital modulation set to 'internal'
2023-04-10 19:30:17.030 [    INFO] (            laser.py:  66) Analog modulation set to 'external'
2023-04-10 19:30:17.976 [    INFO] (            laser.py:  98) Modulation state set to 'continuous'
2023-04-10 19:30:19.416 [    INFO] (            laser.py: 101) Modulation state set to 'modulated'
2023-04-10 19:30:20.124 [    INFO] (            laser.py: 144) Digital modulation set to 'external'
2023-04-10 19:30:21.129 [    INFO] (            laser.py: 108) Laser emission is ON
2023-04-10 19:30:26.631 [    INFO] (            laser.py:  92) Laser diode current set to '99.01%'
2023-04-10 19:30:28.518 [    INFO] (            laser.py: 126) Laser power (real time) set to '50'
2023-04-10 19:30:28.519 [ WARNING] (            laser.py:  43) Failed to set command 'PM=50'
2023-04-10 19:30:28.520 [ WARNING] (            laser.py:  44) Response from Device :'PM=50.0'
2023-04-10 19:30:29.043 [    INFO] (            laser.py:  92) Laser diode current set to '99.01%'
2023-04-10 19:30:37.020 [    INFO] (            laser.py: 111) Laser emission is OFF
2023-04-10 19:30:38.362 [    INFO] (            laser.py:  55) Analog control mode set to 'power'
2023-04-10 19:30:39.321 [    INFO] (            laser.py:  58) Analog control mode set to 'current'
2023-04-10 19:30:39.974 [    INFO] (            laser.py:  69) Analog modulation set to 'internal'
2023-04-10 19:30:40.516 [    INFO] (            laser.py:  66) Analog modulation set to 'external'
2023-04-10 19:30:41.693 [    INFO] (            laser.py:  98) Modulation state set to 'continuous'
2023-04-10 19:30:43.260 [    INFO] (            laser.py: 101) Modulation state set to 'modulated'
2023-04-10 19:30:43.875 [    INFO] (            laser.py:  69) Analog modulation set to 'internal'
2023-04-10 19:30:44.811 [    INFO] (            laser.py:  98) Modulation state set to 'continuous'
2023-04-10 19:30:45.710 [    INFO] (            laser.py: 101) Modulation state set to 'modulated'
2023-04-10 19:30:46.685 [    INFO] (            laser.py: 147) Digital modulation set to 'internal'
2023-04-10 19:30:47.045 [    INFO] (            laser.py: 144) Digital modulation set to 'external'
2023-04-10 19:30:48.194 [    INFO] (            laser.py:  92) Laser diode current set to '99.01%'
2023-04-10 19:30:48.310 [    INFO] (            laser.py: 108) Laser emission is ON
2023-04-10 19:30:52.207 [    INFO] (            laser.py:  92) Laser diode current set to '99.01%'
2023-04-10 19:32:08.610 [    INFO] (           server.py: 156) accepted ('127.0.0.1', 9250) with fd 1776
2023-04-10 19:32:08.611 [    INFO] (           server.py: 199) welcome ('127.0.0.1', 9250)
2023-04-10 19:32:08.612 [    INFO] (           inserv.py: 350) client <rpyc.core.protocol.Connection 'conn4' object at 0x0000023404306590> connected
2023-04-10 19:32:08.630 [   DEBUG] (         protocol.py: 331) Exception caught
Traceback (most recent call last):
  File "C:\Users\ctcheung\.conda\envs\hfnvenv\lib\site-packages\rpyc\core\protocol.py", line 324, in _dispatch_request
    res = self._HANDLERS[handler](self, *args)
  File "C:\Users\ctcheung\.conda\envs\hfnvenv\lib\site-packages\rpyc\core\protocol.py", line 609, in _handle_call
    return obj(*args, **dict(kwargs))
  File "C:\Users\ctcheung\OneDrive - The University of Chicago\UChicago Postgrad\Research\High Magnetic Field NV\program\diamonddash\hardware\laser\laser.py", line 48, in send_query
    return super().send(input).encode('ASCII')
AttributeError: 'int' object has no attribute 'encode'
2023-04-11 17:10:59.709 [    INFO] (            laser.py:  92) Laser diode current set to '99.01%'
2023-04-11 17:11:03.765 [    INFO] (            laser.py:  92) Laser diode current set to '99.01%'
2023-04-11 17:11:08.178 [    INFO] (           inserv.py: 354) client <rpyc.core.protocol.Connection 'conn4' object at 0x0000023404306590> disconnected
2023-04-11 17:11:08.178 [    INFO] (           inserv.py: 354) client <rpyc.core.protocol.Connection 'conn3' object at 0x00000234043060B0> disconnected
2023-04-11 17:11:08.185 [    INFO] (           server.py: 206) goodbye ('127.0.0.1', 9250)
2023-04-11 17:11:08.185 [    INFO] (           server.py: 206) goodbye ('127.0.0.1', 8838)
